Workbook

Sheet Start_Here
A1: Demand & Inventory Planning Model (Excel V1: learning and validation prototype)
A2: Methodological source of truth for the later Python / Streamlit application. All data synthetic. No macros.
A4: Business question: Given what we expect customers to buy, the inventory we currently have, inventory already on order, supplier lead times and basic replenishment economics, which products need attention, when should we reorder them, and approximately how much should we order?
A6: PLANNING CHAIN
A7: Historical Sales -> Simple Forecast -> WAPE / Bias -> Historical Forecast Error -> Safety Stock -> Lead-Time Demand -> Reorder Point -> Inventory Position -> Reorder Decision -> Economic Order Quantity -> Recommended Order -> 12-Week Inventory Projection -> Stockout / Reorder / Excess / Healthy Status -> Simple Historical Backtest
A9: SHEET MAP (in study order)
A10: Study step | B10: Sheet | C10: What it does | D10: What to focus on
A11: 1 | B11: Formula_Guide | C11: Definitions, formulas, examples and limitations for every concept. | D11: Read once before touching numbers.
A12: 2 | B12: Inputs | C12: Global parameters, suppliers (lead time, ordering cost), SKU master and current inventory. | D12: Which cells are inputs (blue on yellow); the fixed snapshot date.
A13: 3 | B13: Demand_History | C13: Tidy table: Week, date, SKU, actual demand (48 SKUs x 104 weeks). | D13: Scroll one SKU; spot stable, variable, growing, declining patterns.
A14: 4 | B14: Forecast_Walkforward | C14: Row per SKU-week: the four walk-forward forecasts, errors (F-A) and absolute errors. | D14: Click a MA4 or SES cell: it only references earlier rows.
A15: 5 | B15: Forecast | C15: Per SKU: WAPE, Bias, Error SD and next-week forecast of each method; selection rule. | D15: Selected method, current forecast, the tolerance logic (MATCH TRUE).
A16: 6 | B16: Replenishment_Plan | C16: Core table: SS, LTD, ROP, IP, weeks of cover, EOQ, trigger, recommended order, status, reason. | D16: Read one row left to right; ROP = when, EOQ = how much.
A17: 7 | B17: Projection | C17: 12-week closing inventory per SKU with existing PO and new order receipts. | D17: Timing of receipts; the zero-within-lead-time flag.
A18: 8 | B18: SKU_Deep_Dive | C18: HERO SHEET: pick a SKU and follow every step with formula, numbers, result and interpretation. | D18: Explain one SKU out loud from history to projected inventory.
A19: 9 | B19: Planner_Overview | C19: KPIs, status summary, two charts and the ranked attention list. | D19: How a planner would start the week.
A20: 10 | B20: Backtest | C20: 16-week replay: 4-week baseline vs forecast + SS + ROP + EOQ, lost sales, no look-ahead. | D20: The trade-off between fill rate, orders and inventory value.
A21: 11 | B21: Validation | C21: Textbook examples plus four SKUs and the backtest recomputed independently in Python: PASS/FAIL. | D21: Confirms the Excel logic before porting it to Python.
A23: CELL LEGEND
A24: Input | B24: Blue text on light yellow: values you may change (Inputs sheet, SKU selectors).
A25: Formula | B25: Black text: calculated. Do not overwrite.
A26: Link | B26: Green text: value pulled from another sheet.
A27: Status shading | B27: Dark grey = STOCKOUT RISK, mid grey = REORDER REQUIRED, light grey = EXCESS STOCK. Status is always written as text too (grayscale-printable).
A29: KEY SIMPLIFICATIONS (V1)
A30: - Fixed supplier lead times; lead-time variability out of scope.
A31: - Flat forecasts (no trend or seasonality); growing items tend to be under-forecast and declining items over-forecast.
A32: - Safety stock = z x Error SD x SQRT(LT): errors assumed roughly normal and independent week to week; the weekly review period is not added to the lead time.
A33: - EOQ ignores quantity discounts, supplier minimums and capacity; one EOQ per weekly review.
A34: - One open PO per SKU at the snapshot; projection is deterministic and includes only today's recommended order.
A35: - Backtest: lost sales, parameters calibrated before the replay, one synthetic scenario; results show trade-offs, not proof.

Sheet Inputs
A1: Inputs: global parameters, suppliers, SKU master and current inventory
A2: Fictitious company: Hearthline Home Online GmbH (home & living e-commerce). One central warehouse. All data synthetic.
A4: Legend: | B4: Blue text on yellow = input you may change | C4: Black text = formula (do not overwrite) | D4: Green text = link pulled from another sheet
A6: GLOBAL PLANNING PARAMETERS
A7: Parameter | B7: Value | C7: Unit | D7: Note
A8: Company | B8: Hearthline Home Online GmbH | C8: text | D8: Fictitious retailer used for the scenario.
A9: Warehouse | B9: DC-01 Central Warehouse | C9: text | D9: Single stocking location (multi-echelon is out of scope).
A10: Model snapshot date | B10: 46202 | C10: date | D10: Fixed planning date = start of planning week 105. TODAY() is deliberately NOT used.
A11: Target service level | B11: 0.95 | C11: % | D11: Probability of not stocking out during lead time (cycle service level). Default 95%.
A12: z-value | B12: =_xlfn.NORM.S.INV(TSL) -> 1.6448536 | C12: number | D12: Formula NORM.S.INV(Target service level). 95% gives about 1.645.
A13: Annual holding rate | B13: 0.2 | C13: % of unit cost / year | D13: Cost of holding one unit for a year as % of its cost (capital, storage, obsolescence).
A14: Weeks per year | B14: 52 | C14: weeks | D14: Used to annualise weekly forecast for EOQ.
A15: Excess-stock threshold | B15: 12 | C15: weeks of cover | D15: Inventory position above this many weeks of forecast demand is flagged EXCESS STOCK.
A16: SES smoothing alpha | B16: 0.3 | C16: 0-1 | D16: Weight on the most recent actual in Simple Exponential Smoothing.
A17: WAPE tie tolerance | B17: 0.01 | C17: WAPE points | D17: If a simpler method is within this WAPE of the best one, the simpler method is selected. 0.01 = 1.0 percentage point.
A18: Forecast evaluation window | B18: 52 | C18: weeks | D18: Number of most recent weeks used for WAPE, Bias and Error SD (allowed 13-52).
A19: History length | B19: 104 | C19: weeks | D19: Structural: 104 weeks per SKU in Demand_History. Do not change without rebuilding.
A20: Evaluation start week | B20: =Weeks_History-Eval_Weeks+1 -> 53 | C20: week # | D20: First week of the evaluation window for live planning.
A21: Backtest length | B21: 16 | C21: weeks | D21: Structural: the Backtest sheet replays the final 16 weeks. Do not change without rebuilding.
A22: Backtest start week | B22: =Weeks_History-BT_Weeks+1 -> 89 | C22: week # | D22: First replayed week.
A23: Backtest calibration start week | B23: =BT_Start_Week-Eval_Weeks -> 37 | C23: week # | D23: Method choice and Error SD for the backtest are estimated only on weeks BEFORE the backtest (no look-ahead).
A24: Backtest calibration end week | B24: =BT_Start_Week-1 -> 88 | C24: week # | D24: Last week of the calibration window.
A25: Baseline policy: weeks of stock | B25: 4 | C25: weeks | D25: Policy A orders up to this many weeks of the trailing 4-week average demand.
A26: Backtest opening stock | B26: 6 | C26: weeks | D26: Both policies start the replay with this many weeks of the trailing 8-week average demand on hand, nothing on order.
A27: Projection horizon | B27: 12 | C27: weeks | D27: Structural: forward projection length on the Projection sheet.
A29: SUPPLIERS (fixed lead times; lead-time variability is out of scope)
A30: Supplier ID | B30: Supplier Name | C30: Lead Time (weeks) | D30: Ordering Cost per Order (€)
A31: SUP-01 | B31: Rhein-Main Kitchenware GmbH | C31: 2 | D31: 40
A32: SUP-02 | B32: Alpina Bath & Textile AG | C32: 3 | D32: 45
A33: SUP-03 | B33: Baltic Linen Works UAB | C33: 4 | D33: 55
A34: SUP-04 | B34: Pearl River Electrics Ltd | C34: 6 | D34: 90
A35: SUP-05 | B35: CleanCare Distribution BV | C35: 1 | D35: 35
A38: SKU MASTER AND CURRENT INVENTORY AT SNAPSHOT DATE
A39: SKU # | B39: SKU | C39: Product Name | D39: Category | E39: Supplier ID | F39: Supplier Lead Time (weeks) | G39: Ordering Cost per Order (€) | H39: Unit Cost (€) | I39: Case Pack (units) | J39: Current On Hand (units) | K39: On Order (open PO units) | L39: Open PO Due Week (1 = week starting snapshot) | M39: Backorders (units) | N39: Synthetic Demand Pattern (info only)
A40: 1 | B40: KIT-001 | C40: Chef's Knife 20cm | D40: Kitchen | E40: SUP-01 | F40: =INDEX(Inputs!$C$31:$C$35,MATCH(E40,Inputs!$A$31:$A$35,0)) -> 2 | G40: =INDEX(Inputs!$D$31:$D$35,MATCH(E40,Inputs!$A$31:$A$35,0)) -> 40 | H40: 18 | I40: 6 | J40: 236 | K40: 0 | M40: 0 | N40: stable
A41: 2 | B41: KIT-002 | C41: Non-Stick Frying Pan 28cm | D41: Kitchen | E41: SUP-01 | F41: =INDEX(Inputs!$C$31:$C$35,MATCH(E41,Inputs!$A$31:$A$35,0)) -> 2 | G41: =INDEX(Inputs!$D$31:$D$35,MATCH(E41,Inputs!$A$31:$A$35,0)) -> 40 | H41: 22 | I41: 4 | J41: 6 | K41: 92 | L41: 1 | M41: 0 | N41: variable
A42: 3 | B42: KIT-003 | C42: Glass Food Storage Set 5pc | D42: Kitchen | E42: SUP-01 | F42: =INDEX(Inputs!$C$31:$C$35,MATCH(E42,Inputs!$A$31:$A$35,0)) -> 2 | G42: =INDEX(Inputs!$D$31:$D$35,MATCH(E42,Inputs!$A$31:$A$35,0)) -> 40 | H42: 15 | I42: 6 | J42: 0 | K42: 0 | M42: 36 | N42: growing
A43: 4 | B43: KIT-004 | C43: Bamboo Cutting Board | D43: Kitchen | E43: SUP-01 | F43: =INDEX(Inputs!$C$31:$C$35,MATCH(E43,Inputs!$A$31:$A$35,0)) -> 2 | G43: =INDEX(Inputs!$D$31:$D$35,MATCH(E43,Inputs!$A$31:$A$35,0)) -> 40 | H43: 9 | I43: 12 | J43: 270 | K43: 0 | M43: 0 | N43: stable
A44: 5 | B44: KIT-005 | C44: Stainless Saucepan 2L | D44: Kitchen | E44: SUP-01 | F44: =INDEX(Inputs!$C$31:$C$35,MATCH(E44,Inputs!$A$31:$A$35,0)) -> 2 | G44: =INDEX(Inputs!$D$31:$D$35,MATCH(E44,Inputs!$A$31:$A$35,0)) -> 40 | H44: 28 | I44: 4 | J44: 334 | K44: 0 | M44: 0 | N44: declining
A45: 6 | B45: KIT-006 | C45: Silicone Utensil Set | D45: Kitchen | E45: SUP-01 | F45: =INDEX(Inputs!$C$31:$C$35,MATCH(E45,Inputs!$A$31:$A$35,0)) -> 2 | G45: =INDEX(Inputs!$D$31:$D$35,MATCH(E45,Inputs!$A$31:$A$35,0)) -> 40 | H45: 12 | I45: 10 | J45: 378 | K45: 0 | M45: 0 | N45: variable
...

Sheet Demand_History
A1: Week | B1: Week Start Date | C1: SKU | D1: Actual Demand (units)
A2: 1 | B2: 45474 | C2: KIT-001 | D2: 62
A3: 2 | B3: 45481 | C3: KIT-001 | D3: 58
A4: 3 | B4: 45488 | C4: KIT-001 | D4: 53
A5: 4 | B5: 45495 | C5: KIT-001 | D5: 56
A6: 5 | B6: 45502 | C6: KIT-001 | D6: 52
A7: 6 | B7: 45509 | C7: KIT-001 | D7: 60
A8: 7 | B8: 45516 | C8: KIT-001 | D8: 71
A9: 8 | B9: 45523 | C9: KIT-001 | D9: 56
A10: 9 | B10: 45530 | C10: KIT-001 | D10: 55
A11: 10 | B11: 45537 | C11: KIT-001 | D11: 64
A12: 11 | B12: 45544 | C12: KIT-001 | D12: 63
A13: 12 | B13: 45551 | C13: KIT-001 | D13: 61
... A4993: 104 | B4993: 46195 | C4993: CLN-011 | D4993: 45

Sheet Forecast
A1: Forecast: walk-forward method comparison and selection per SKU
A2: WAPE = SUM|F-A| / SUM(A). Bias = SUM(F-A) / SUM(A). Error SD = STDEV.S of out-of-sample errors (F-A). Selection: lowest WAPE; a simpler method wins if within the WAPE tolerance. Simplicity order: Naive < MA4 < MA8 < SES.
A3: Portfolio WAPE (selected methods, volume-weighted): | E3: =SUM(AJ7:AJ54)/SUM(H7:H54) -> 0.14220804
A5: ROW LOOKUPS | H5: LIVE PLANNING: evaluation window = weeks Eval_Start_Week to 104 (default 53-104) | AK5: BACKTEST CALIBRATION: weeks Cal_Start_Week to Cal_End_Week (default 37-88), uses no data from the backtest weeks
A6: SKU | B6: Product | C6: First Row in history | D6: Last Row | E6: Eval First Row | F6: Calib First Row | G6: Calib Last Row | H6: Eval Actual Sum | I6: WAPE Naive | J6: WAPE MA4 | K6: WAPE MA8 | L6: WAPE SES | M6: Bias Naive | N6: Bias MA4 | O6: Bias MA8 | P6: Bias SES | Q6: Err SD Naive | R6: Err SD MA4 | S6: Err SD MA8 | T6: Err SD SES | U6: Next-Wk Fcst Naive | V6: Next-Wk Fcst MA4 | W6: Next-Wk Fcst MA8 | X6: Next-Wk Fcst SES | Y6: Best WAPE | Z6: Naive within tol? | AA6: MA4 within tol? | AB6: MA8 within tol? | AC6: SES within tol? | AD6: Selected Method # | AE6: Selected Forecast Method | AF6: Current Weekly Forecast | AG6: Selected WAPE | AH6: Selected Bias | AI6: Selected Error SD | AJ6: Selected Abs Error Sum | AK6: Calib Actual Sum | AL6: Calib WAPE Naive | AM6: Calib WAPE MA4 | AN6: Calib WAPE MA8 | AO6: Calib WAPE SES | AP6: Calib Err SD Naive | AQ6: Calib Err SD MA4 | AR6: Calib Err SD MA8 | AS6: Calib Err SD SES | AT6: Calib Best WAPE | AU6: Calib Naive within tol? | AV6: Calib MA4 within tol? | AW6: Calib MA8 within tol? | AX6: Calib SES within tol? | AY6: Calib Selected # | AZ6: Calib Selected Method | BA6: Calib Error SD (selected)
A7: =Inputs!B40 -> KIT-001 | B7: =Inputs!C40 -> Chef's Knife 20cm | C7: =MATCH(A7,Demand_History!$C:$C,0) -> 2 | D7: =C7+Weeks_History-1 -> 105 | E7: =C7+Eval_Start_Week-1 -> 54 | F7: =C7+Cal_Start_Week-1 -> 38 | G7: =C7+Cal_End_Week-1 -> 89 | H7: =SUM(INDEX(Forecast_Walkforward!$C:$C,$E7):INDEX(Forecast_Walkforward!$C:$C,$D7)) -> 3104 | I7: =SUM(INDEX(Forecast_Walkforward!$L:$L,$E7):INDEX(Forecast_Walkforward!$L:$L,$D7))/$H7 -> 0.13659794 | J7: =SUM(INDEX(Forecast_Walkforward!$M:$M,$E7):INDEX(Forecast_Walkforward!$M:$M,$D7))/$H7 -> 0.10647552 | K7: =SUM(INDEX(Forecast_Walkforward!$N:$N,$E7):INDEX(Forecast_Walkforward!$N:$N,$D7))/$H7 -> 0.096488402 | L7: =SUM(INDEX(Forecast_Walkforward!$O:$O,$E7):INDEX(Forecast_Walkforward!$O:$O,$D7))/$H7 -> 0.1024709 | M7: =SUM(INDEX(Forecast_Walkforward!$H:$H,$E7):INDEX(Forecast_Walkforward!$H:$H,$D7))/$H7 -> 0.0025773196 | N7: =SUM(INDEX(Forecast_Walkforward!$I:$I,$E7):INDEX(Forecast_Walkforward!$I:$I,$D7))/$H7 -> -0.0012886598 | O7: =SUM(INDEX(Forecast_Walkforward!$J:$J,$E7):INDEX(Forecast_Walkforward!$J:$J,$D7))/$H7 -> 0.003382732 | P7: =SUM(INDEX(Forecast_Walkforward!$K:$K,$E7):INDEX(Forecast_Walkforward!$K:$K,$D7))/$H7 -> 0.001049945 | Q7: =_xlfn.STDEV.S(INDEX(Forecast_Walkforward!$H:$H,$E7):INDEX(Forecast_Walkforward!$H:$H,$D7)) -> 9.9200423 | R7: =_xlfn.STDEV.S(INDEX(Forecast_Walkforward!$I:$I,$E7):INDEX(Forecast_Walkforward!$I:$I,$D7)) -> 8.0702398 | S7: =_xlfn.STDEV.S(INDEX(Forecast_Walkforward!$J:$J,$E7):INDEX(Forecast_Walkforward!$J:$J,$D7)) -> 7.6105075 | T7: =_xlfn.STDEV.S(INDEX(Forecast_Walkforward!$K:$K,$E7):INDEX(Forecast_Walkforward!$K:$K,$D7)) -> 7.7251244 | U7: =INDEX(Forecast_Walkforward!$C:$C,$D7) -> 53 | V7: =AVERAGE(INDEX(Forecast_Walkforward!$C:$C,$D7-3):INDEX(Forecast_Walkforward!$C:$C,$D7)) -> 61.25 | W7: =AVERAGE(INDEX(Forecast_Walkforward!$C:$C,$D7-7):INDEX(Forecast_Walkforward!$C:$C,$D7)) -> 57.125 | X7: =SES_Alpha*INDEX(Forecast_Walkforward!$C:$C,$D7)+(1-SES_Alpha)*INDEX(Forecast_Walkforward!$G:$G,$D7) -> 59.718987 | Y7: =MIN(I7:L7) -> 0.096488402 | Z7: =I7<=$Y7+WAPE_Tol -> FALSE | AA7: =J7<=$Y7+WAPE_Tol -> TRUE | AB7: =K7<=$Y7+WAPE_Tol -> TRUE | AC7: =L7<=$Y7+WAPE_Tol -> TRUE | AD7: =MATCH(TRUE(),Z7:AC7,0) -> 2 | AE7: =CHOOSE(AD7,"Naive","MA4","MA8","SES") -> MA4 | AF7: =INDEX(U7:X7,AD7) -> 61.25 | AG7: =INDEX(I7:L7,AD7) -> 0.10647552 | AH7: =INDEX(M7:P7,AD7) -> -0.0012886598 | AI7: =INDEX(Q7:T7,AD7) -> 8.0702398 | AJ7: =AG7*H7 -> 330.5 | AK7: =SUM(INDEX(Forecast_Walkforward!$C:$C,$F7):INDEX(Forecast_Walkforward!$C:$C,$G7)) -> 3127 | AL7: =SUM(INDEX(Forecast_Walkforward!$L:$L,$F7):INDEX(Forecast_Walkforward!$L:$L,$G7))/$AK7 -> 0.1371922 | AM7: =SUM(INDEX(Forecast_Walkforward!$M:$M,$F7):INDEX(Forecast_Walkforward!$M:$M,$G7))/$AK7 -> 0.10089543 | AN7: =SUM(INDEX(Forecast_Walkforward!$N:$N,$F7):INDEX(Forecast_Walkforward!$N:$N,$G7))/$AK7 -> 0.094099776 | AO7: =SUM(INDEX(Forecast_Walkforward!$O:$O,$F7):INDEX(Forecast_Walkforward!$O:$O,$G7))/$AK7 -> 0.098986363 | AP7: =_xlfn.STDEV.S(INDEX(Forecast_Walkforward!$H:$H,$F7):INDEX(Forecast_Walkforward!$H:$H,$G7)) -> 10.100905 | AQ7: =_xlfn.STDEV.S(INDEX(Forecast_Walkforward!$I:$I,$F7):INDEX(Forecast_Walkforward!$I:$I,$G7)) -> 7.7446218 | AR7: =_xlfn.STDEV.S(INDEX(Forecast_Walkforward!$J:$J,$F7):INDEX(Forecast_Walkforward!$J:$J,$G7)) -> 7.2709769 | AS7: =_xlfn.STDEV.S(INDEX(Forecast_Walkforward!$K:$K,$F7):INDEX(Forecast_Walkforward!$K:$K,$G7)) -> 7.5877795 | AT7: =MIN(AL7:AO7) -> 0.094099776 | AU7: =AL7<=$AT7+WAPE_Tol -> FALSE | AV7: =AM7<=$AT7+WAPE_Tol -> TRUE | AW7: =AN7<=$AT7+WAPE_Tol -> TRUE | AX7: =AO7<=$AT7+WAPE_Tol -> TRUE | AY7: =MATCH(TRUE(),AU7:AX7,0) -> 2 | AZ7: =CHOOSE(AY7,"Naive","MA4","MA8","SES") -> MA4 | BA7: =INDEX(AP7:AS7,AY7) -> 7.7446218
A8: =Inputs!B41 -> KIT-002 | B8: =Inputs!C41 -> Non-Stick Frying Pan 28cm | C8: =MATCH(A8,Demand_History!$C:$C,0) -> 106 | D8: =C8+Weeks_History-1 -> 209 | E8: =C8+Eval_Start_Week-1 -> 158 | F8: =C8+Cal_Start_Week-1 -> 142 | G8: =C8+Cal_End_Week-1 -> 193 | H8: =SUM(INDEX(Forecast_Walkforward!$C:$C,$E8):INDEX(Forecast_Walkforward!$C:$C,$D8)) -> 2383 | I8: =SUM(INDEX(Forecast_Walkforward!$L:$L,$E8):INDEX(Forecast_Walkforward!$L:$L,$D8))/$H8 -> 0.35459505 | J8: =SUM(INDEX(Forecast_Walkforward!$M:$M,$E8):INDEX(Forecast_Walkforward!$M:$M,$D8))/$H8 -> 0.27276542 | K8: =SUM(INDEX(Forecast_Walkforward!$N:$N,$E8):INDEX(Forecast_Walkforward!$N:$N,$D8))/$H8 -> 0.26778221 | L8: =SUM(INDEX(Forecast_Walkforward!$O:$O,$E8):INDEX(Forecast_Walkforward!$O:$O,$D8))/$H8 -> 0.27505341 | M8: =SUM(INDEX(Forecast_Walkforward!$H:$H,$E8):INDEX(Forecast_Walkforward!$H:$H,$D8))/$H8 -> 0.0012589173 | N8: =SUM(INDEX(Forecast_Walkforward!$I:$I,$E8):INDEX(Forecast_Walkforward!$I:$I,$D8))/$H8 -> -0.0035669324 | O8: =SUM(INDEX(Forecast_Walkforward!$J:$J,$E8):INDEX(Forecast_Walkforward!$J:$J,$D8))/$H8 -> -0.015054553 | P8: =SUM(INDEX(Forecast_Walkforward!$K:$K,$E8):INDEX(Forecast_Walkforward!$K:$K,$D8))/$H8 -> -0.0092835341 | Q8: =_xlfn.STDEV.S(INDEX(Forecast_Walkforward!$H:$H,$E8):INDEX(Forecast_Walkforward!$H:$H,$D8)) -> 20.865032 | R8: =_xlfn.STDEV.S(INDEX(Forecast_Walkforward!$I:$I,$E8):INDEX(Forecast_Walkforward!$I:$I,$D8)) -> 16.126331 | S8: =_xlfn.STDEV.S(INDEX(Forecast_Walkforward!$J:$J,$E8):INDEX(Forecast_Walkforward!$J:$J,$D8)) -> 15.250371 | T8: =_xlfn.STDEV.S(INDEX(Forecast_Walkforward!$K:$K,$E8):INDEX(Forecast_Walkforward!$K:$K,$D8)) -> 15.813458 | U8: =INDEX(Forecast_Walkforward!$C:$C,$D8) -> 30 | V8: =AVERAGE(INDEX(Forecast_Walkforward!$C:$C,$D8-3):INDEX(Forecast_Walkforward!$C:$C,$D8)) -> 33.5 | W8: =AVERAGE(INDEX(Forecast_Walkforward!$C:$C,$D8-7):INDEX(Forecast_Walkforward!$C:$C,$D8)) -> 48.375 | X8: =SES_Alpha*INDEX(Forecast_Walkforward!$C:$C,$D8)+(1-SES_Alpha)*INDEX(Forecast_Walkforward!$G:$G,$D8) -> 41.513413 | Y8: =MIN(I8:L8) -> 0.26778221 | Z8: =I8<=$Y8+WAPE_Tol -> FALSE | AA8: =J8<=$Y8+WAPE_Tol -> TRUE | AB8: =K8<=$Y8+WAPE_Tol -> TRUE | AC8: =L8<=$Y8+WAPE_Tol -> TRUE | AD8: =MATCH(TRUE(),Z8:AC8,0) -> 2 | AE8: =CHOOSE(AD8,"Naive","MA4","MA8","SES") -> MA4 | AF8: =INDEX(U8:X8,AD8) -> 33.5 | AG8: =INDEX(I8:L8,AD8) -> 0.27276542 | AH8: =INDEX(M8:P8,AD8) -> -0.0035669324 | AI8: =INDEX(Q8:T8,AD8) -> 16.126331 | AJ8: =AG8*H8 -> 650 | AK8: =SUM(INDEX(Forecast_Walkforward!$C:$C,$F8):INDEX(Forecast_Walkforward!$C:$C,$G8)) -> 2220 | AL8: =SUM(INDEX(Forecast_Walkforward!$L:$L,$F8):INDEX(Forecast_Walkforward!$L:$L,$G8))/$AK8 -> 0.33333333 | AM8: =SUM(INDEX(Forecast_Walkforward!$M:$M,$F8):INDEX(Forecast_Walkforward!$M:$M,$G8))/$AK8 -> 0.25236486 | AN8: =SUM(INDEX(Forecast_Walkforward!$N:$N,$F8):INDEX(Forecast_Walkforward!$N:$N,$G8))/$AK8 -> 0.2446509 | AO8: =SUM(INDEX(Forecast_Walkforward!$O:$O,$F8):INDEX(Forecast_Walkforward!$O:$O,$G8))/$AK8 -> 0.2467857 | AP8: =_xlfn.STDEV.S(INDEX(Forecast_Walkforward!$H:$H,$F8):INDEX(Forecast_Walkforward!$H:$H,$G8)) -> 18.279587 | AQ8: =_xlfn.STDEV.S(INDEX(Forecast_Walkforward!$I:$I,$F8):INDEX(Forecast_Walkforward!$I:$I,$G8)) -> 14.122994 | AR8: =_xlfn.STDEV.S(INDEX(Forecast_Walkforward!$J:$J,$F8):INDEX(Forecast_Walkforward!$J:$J,$G8)) -> 13.29631 | AS8: =_xlfn.STDEV.S(INDEX(Forecast_Walkforward!$K:$K,$F8):INDEX(Forecast_Walkforward!$K:$K,$G8)) -> 13.783621 | AT8: =MIN(AL8:AO8) -> 0.2446509 | AU8: =AL8<=$AT8+WAPE_Tol -> FALSE | AV8: =AM8<=$AT8+WAPE_Tol -> TRUE | AW8: =AN8<=$AT8+WAPE_Tol -> TRUE | AX8: =AO8<=$AT8+WAPE_Tol -> TRUE | AY8: =MATCH(TRUE(),AU8:AX8,0) -> 2 | AZ8: =CHOOSE(AY8,"Naive","MA4","MA8","SES") -> MA4 | BA8: =INDEX(AP8:AS8,AY8) -> 14.122994
A9: =Inputs!B42 -> KIT-003 | B9: =Inputs!C42 -> Glass Food Storage Set 5pc | C9: =MATCH(A9,Demand_History!$C:$C,0) -> 210 | D9: =C9+Weeks_History-1 -> 313 | E9: =C9+Eval_Start_Week-1 -> 262 | F9: =C9+Cal_Start_Week-1 -> 246 | G9: =C9+Cal_End_Week-1 -> 297 | H9: =SUM(INDEX(Forecast_Walkforward!$C:$C,$E9):INDEX(Forecast_Walkforward!$C:$C,$D9)) -> 4472 | I9: =SUM(INDEX(Forecast_Walkforward!$L:$L,$E9):INDEX(Forecast_Walkforward!$L:$L,$D9))/$H9 -> 0.13528623 | J9: =SUM(INDEX(Forecast_Walkforward!$M:$M,$E9):INDEX(Forecast_Walkforward!$M:$M,$D9))/$H9 -> 0.1151051 | K9: =SUM(INDEX(Forecast_Walkforward!$N:$N,$E9):INDEX(Forecast_Walkforward!$N:$N,$D9))/$H9 -> 0.10336538 | L9: =SUM(INDEX(Forecast_Walkforward!$O:$O,$E9):INDEX(Forecast_Walkforward!$O:$O,$D9))/$H9 -> 0.10735683 | M9: =SUM(INDEX(Forecast_Walkforward!$H:$H,$E9):INDEX(Forecast_Walkforward!$H:$H,$D9))/$H9 -> -0.0033542039 | N9: =SUM(INDEX(Forecast_Walkforward!$I:$I,$E9):INDEX(Forecast_Walkforward!$I:$I,$D9))/$H9 -> -0.012690072 | O9: =SUM(INDEX(Forecast_Walkforward!$J:$J,$E9):INDEX(Forecast_Walkforward!$J:$J,$D9))/$H9 -> -0.022976297 | P9: =SUM(INDEX(Forecast_Walkforward!$K:$K,$E9):INDEX(Forecast_Walkforward!$K:$K,$D9))/$H9 -> -0.017137407 | Q9: =_xlfn.STDEV.S(INDEX(Forecast_Walkforward!$H:$H,$E9):INDEX(Forecast_Walkforward!$H:$H,$D9)) -> 15.363997 | R9: =_xlfn.STDEV.S(INDEX(Forecast_Walkforward!$I:$I,$E9):INDEX(Forecast_Walkforward!$I:$I,$D9)) -> 12.625452 | S9: =_xlfn.STDEV.S(INDEX(Forecast_Walkforward!$J:$J,$E9):INDEX(Forecast_Walkforward!$J:$J,$D9)) -> 11.354526 | T9: =_xlfn.STDEV.S(INDEX(Forecast_Walkforward!$K:$K,$E9):INDEX(Forecast_Walkforward!$K:$K,$D9)) -> 11.893202 | U9: =INDEX(Forecast_Walkforward!$C:$C,$D9) -> 95 | V9: =AVERAGE(INDEX(Forecast_Walkforward!$C:$C,$D9-3):INDEX(Forecast_Walkforward!$C:$C,$D9)) -> 98 | W9: =AVERAGE(INDEX(Forecast_Walkforward!$C:$C,$D9-7):INDEX(Forecast_Walkforward!$C:$C,$D9)) -> 95.125 | X9: =SES_Alpha*INDEX(Forecast_Walkforward!$C:$C,$D9)+(1-SES_Alpha)*INDEX(Forecast_Walkforward!$G:$G,$D9) -> 95.660303 | Y9: =MIN(I9:L9) -> 0.10336538 | Z9: =I9<=$Y9+WAPE_Tol -> FALSE | AA9: =J9<=$Y9+WAPE_Tol -> FALSE | AB9: =K9<=$Y9+WAPE_Tol -> TRUE | AC9: =L9<=$Y9+WAPE_Tol -> TRUE | AD9: =MATCH(TRUE(),Z9:AC9,0) -> 3 | AE9: =CHOOSE(AD9,"Naive","MA4","MA8","SES") -> MA8 | AF9: =INDEX(U9:X9,AD9) -> 95.125 | AG9: =INDEX(I9:L9,AD9) -> 0.10336538 | AH9: =INDEX(M9:P9,AD9) -> -0.022976297 | AI9: =INDEX(Q9:T9,AD9) -> 11.354526 | AJ9: =AG9*H9 -> 462.25 | AK9: =SUM(INDEX(Forecast_Walkforward!$C:$C,$F9):INDEX(Forecast_Walkforward!$C:$C,$G9)) -> 3961 | AL9: =SUM(INDEX(Forecast_Walkforward!$L:$L,$F9):INDEX(Forecast_Walkforward!$L:$L,$G9))/$AK9 -> 0.15576875 | AM9: =SUM(INDEX(Forecast_Walkforward!$M:$M,$F9):INDEX(Forecast_Walkforward!$M:$M,$G9))/$AK9 -> 0.13153244 | AN9: =SUM(INDEX(Forecast_Walkforward!$N:$N,$F9):INDEX(Forecast_Walkforward!$N:$N,$G9))/$AK9 -> 0.12414794 | AO9: =SUM(INDEX(Forecast_Walkforward!$O:$O,$F9):INDEX(Forecast_Walkforward!$O:$O,$G9))/$AK9 -> 0.12472271 | AP9: =_xlfn.STDEV.S(INDEX(Forecast_Walkforward!$H:$H,$F9):INDEX(Forecast_Walkforward!$H:$H,$G9)) -> 15.468976 | AQ9: =_xlfn.STDEV.S(INDEX(Forecast_Walkforward!$I:$I,$F9):INDEX(Forecast_Walkforward!$I:$I,$G9)) -> 12.744602 | AR9: =_xlfn.STDEV.S(INDEX(Forecast_Walkforward!$J:$J,$F9):INDEX(Forecast_Walkforward!$J:$J,$G9)) -> 11.998749 | AS9: =_xlfn.STDEV.S(INDEX(Forecast_Walkforward!$K:$K,$F9):INDEX(Forecast_Walkforward!$K:$K,$G9)) -> 12.246729 | AT9: =MIN(AL9:AO9) -> 0.12414794 | AU9: =AL9<=$AT9+WAPE_Tol -> FALSE | AV9: =AM9<=$AT9+WAPE_Tol -> TRUE | AW9: =AN9<=$AT9+WAPE_Tol -> TRUE | AX9: =AO9<=$AT9+WAPE_Tol -> TRUE | AY9: =MATCH(TRUE(),AU9:AX9,0) -> 2 | AZ9: =CHOOSE(AY9,"Naive","MA4","MA8","SES") -> MA4 | BA9: =INDEX(AP9:AS9,AY9) -> 12.744602
A10: =Inputs!B43 -> KIT-004 | B10: =Inputs!C43 -> Bamboo Cutting Board | C10: =MATCH(A10,Demand_History!$C:$C,0) -> 314 | D10: =C10+Weeks_History-1 -> 417 | E10: =C10+Eval_Start_Week-1 -> 366 | F10: =C10+Cal_Start_Week-1 -> 350 | G10: =C10+Cal_End_Week-1 -> 401 | H10: =SUM(INDEX(Forecast_Walkforward!$C:$C,$E10):INDEX(Forecast_Walkforward!$C:$C,$D10)) -> 4668 | I10: =SUM(INDEX(Forecast_Walkforward!$L:$L,$E10):INDEX(Forecast_Walkforward!$L:$L,$D10))/$H10 -> 0.12253642 | J10: =SUM(INDEX(Forecast_Walkforward!$M:$M,$E10):INDEX(Forecast_Walkforward!$M:$M,$D10))/$H10 -> 0.10689803 | K10: =SUM(INDEX(Forecast_Walkforward!$N:$N,$E10):INDEX(Forecast_Walkforward!$N:$N,$D10))/$H10 -> 0.09733826 | L10: =SUM(INDEX(Forecast_Walkforward!$O:$O,$E10):INDEX(Forecast_Walkforward!$O:$O,$D10))/$H10 -> 0.10060173 | M10: =SUM(INDEX(Forecast_Walkforward!$H:$H,$E10):INDEX(Forecast_Walkforward!$H:$H,$D10))/$H10 -> -0.0072836332 | N10: =SUM(INDEX(Forecast_Walkforward!$I:$I,$E10):INDEX(Forecast_Walkforward!$I:$I,$D10))/$H10 -> -0.0099614396 | O10: =SUM(INDEX(Forecast_Walkforward!$J:$J,$E10):INDEX(Forecast_Walkforward!$J:$J,$D10))/$H10 -> -0.008863539 | P10: =SUM(INDEX(Forecast_Walkforward!$K:$K,$E10):INDEX(Forecast_Walkforward!$K:$K,$D10))/$H10 -> -0.0087757022 | Q10: =_xlfn.STDEV.S(INDEX(Forecast_Walkforward!$H:$H,$E10):INDEX(Forecast_Walkforward!$H:$H,$D10)) -> 13.846334 | R10: =_xlfn.STDEV.S(INDEX(Forecast_Walkforward!$I:$I,$E10):INDEX(Forecast_Walkforward!$I:$I,$D10)) -> 11.467916 | S10: =_xlfn.STDEV.S(INDEX(Forecast_Walkforward!$J:$J,$E10):INDEX(Forecast_Walkforward!$J:$J,$D10)) -> 10.507672 | T10: =_xlfn.STDEV.S(INDEX(Forecast_Walkforward!$K:$K,$E10):INDEX(Forecast_Walkforward!$K:$K,$D10)) -> 10.897646 | U10: =INDEX(Forecast_Walkforward!$C:$C,$D10) -> 105 | V10: =AVERAGE(INDEX(Forecast_Walkforward!$C:$C,$D10-3):INDEX(Forecast_Walkforward!$C:$C,$D10)) -> 96.5 | W10: =AVERAGE(INDEX(Forecast_Walkforward!$C:$C,$D10-7):INDEX(Forecast_Walkforward!$C:$C,$D10)) -> 94.75 | X10: =SES_Alpha*INDEX(Forecast_Walkforward!$C:$C,$D10)+(1-SES_Alpha)*INDEX(Forecast_Walkforward!$G:$G,$D10) -> 96.693918 | Y10: =MIN(I10:L10) -> 0.09733826 | Z10: =I10<=$Y10+WAPE_Tol -> FALSE | AA10: =J10<=$Y10+WAPE_Tol -> TRUE | AB10: =K10<=$Y10+WAPE_Tol -> TRUE | AC10: =L10<=$Y10+WAPE_Tol -> TRUE | AD10: =MATCH(TRUE(),Z10:AC10,0) -> 2 | AE10: =CHOOSE(AD10,"Naive","MA4","MA8","SES") -> MA4 | AF10: =INDEX(U10:X10,AD10) -> 96.5 | AG10: =INDEX(I10:L10,AD10) -> 0.10689803 | AH10: =INDEX(M10:P10,AD10) -> -0.0099614396 | AI10: =INDEX(Q10:T10,AD10) -> 11.467916 | AJ10: =AG10*H10 -> 499 | AK10: =SUM(INDEX(Forecast_Walkforward!$C:$C,$F10):INDEX(Forecast_Walkforward!$C:$C,$G10)) -> 4630 | AL10: =SUM(INDEX(Forecast_Walkforward!$L:$L,$F10):INDEX(Forecast_Walkforward!$L:$L,$G10))/$AK10 -> 0.10194384 | AM10: =SUM(INDEX(Forecast_Walkforward!$M:$M,$F10):INDEX(Forecast_Walkforward!$M:$M,$G10))/$AK10 -> 0.092278618 | AN10: =SUM(INDEX(Forecast_Walkforward!$N:$N,$F10):INDEX(Forecast_Walkforward!$N:$N,$G10))/$AK10 -> 0.08336933 | AO10: =SUM(INDEX(Forecast_Walkforward!$O:$O,$F10):INDEX(Forecast_Walkforward!$O:$O,$G10))/$AK10 -> 0.084538399 | AP10: =_xlfn.STDEV.S(INDEX(Forecast_Walkforward!$H:$H,$F10):INDEX(Forecast_Walkforward!$H:$H,$G10)) -> 11.468364 | AQ10: =_xlfn.STDEV.S(INDEX(Forecast_Walkforward!$I:$I,$F10):INDEX(Forecast_Walkforward!$I:$I,$G10)) -> 10.552742 | AR10: =_xlfn.STDEV.S(INDEX(Forecast_Walkforward!$J:$J,$F10):INDEX(Forecast_Walkforward!$J:$J,$G10)) -> 9.6472278 | AS10: =_xlfn.STDEV.S(INDEX(Forecast_Walkforward!$K:$K,$F10):INDEX(Forecast_Walkforward!$K:$K,$G10)) -> 9.6969871 | AT10: =MIN(AL10:AO10) -> 0.08336933 | AU10: =AL10<=$AT10+WAPE_Tol -> FALSE | AV10: =AM10<=$AT10+WAPE_Tol -> TRUE | AW10: =AN10<=$AT10+WAPE_Tol -> TRUE | AX10: =AO10<=$AT10+WAPE_Tol -> TRUE | AY10: =MATCH(TRUE(),AU10:AX10,0) -> 2 | AZ10: =CHOOSE(AY10,"Naive","MA4","MA8","SES") -> MA4 | BA10: =INDEX(AP10:AS10,AY10) -> 10.552742
A11: =Inputs!B44 -> KIT-005 | B11: =Inputs!C44 -> Stainless Saucepan 2L | C11: =MATCH(A11,Demand_History!$C:$C,0) -> 418 | D11: =C11+Weeks_History-1 -> 521 | E11: =C11+Eval_Start_Week-1 -> 470 | F11: =C11+Cal_Start_Week-1 -> 454 | G11: =C11+Cal_End_Week-1 -> 505 | H11: =SUM(INDEX(Forecast_Walkforward!$C:$C,$E11):INDEX(Forecast_Walkforward!$C:$C,$D11)) -> 1441 | I11: =SUM(INDEX(Forecast_Walkforward!$L:$L,$E11):INDEX(Forecast_Walkforward!$L:$L,$D11))/$H11 -> 0.17071478 | J11: =SUM(INDEX(Forecast_Walkforward!$M:$M,$E11):INDEX(Forecast_Walkforward!$M:$M,$D11))/$H11 -> 0.15076336 | K11: =SUM(INDEX(Forecast_Walkforward!$N:$N,$E11):INDEX(Forecast_Walkforward!$N:$N,$D11))/$H11 -> 0.13861901 | L11: =SUM(INDEX(Forecast_Walkforward!$O:$O,$E11):INDEX(Forecast_Walkforward!$O:$O,$D11))/$H11 -> 0.1401491 | M11: =SUM(INDEX(Forecast_Walkforward!$H:$H,$E11):INDEX(Forecast_Walkforward!$H:$H,$D11))/$H11 -> 0.0055517002 | N11: =SUM(INDEX(Forecast_Walkforward!$I:$I,$E11):INDEX(Forecast_Walkforward!$I:$I,$D11))/$H11 -> 0.018563498 | O11: =SUM(INDEX(Forecast_Walkforward!$J:$J,$E11):INDEX(Forecast_Walkforward!$J:$J,$D11))/$H11 -> 0.031575295 | P11: =SUM(INDEX(Forecast_Walkforward!$K:$K,$E11):INDEX(Forecast_Walkforward!$K:$K,$D11))/$H11 -> 0.023456009 | Q11: =_xlfn.STDEV.S(INDEX(Forecast_Walkforward!$H:$H,$E11):INDEX(Forecast_Walkforward!$H:$H,$D11)) -> 6.3288465 | R11: =_xlfn.STDEV.S(INDEX(Forecast_Walkforward!$I:$I,$E11):INDEX(Forecast_Walkforward!$I:$I,$D11)) -> 5.0218672 | S11: =_xlfn.STDEV.S(INDEX(Forecast_Walkforward!$J:$J,$E11):INDEX(Forecast_Walkforward!$J:$J,$D11)) -> 4.6755649 | T11: =_xlfn.STDEV.S(INDEX(Forecast_Walkforward!$K:$K,$E11):INDEX(Forecast_Walkforward!$K:$K,$D11)) -> 4.8040358 | U11: =INDEX(Forecast_Walkforward!$C:$C,$D11) -> 23 | V11: =AVERAGE(INDEX(Forecast_Walkforward!$C:$C,$D11-3):INDEX(Forecast_Walkforward!$C:$C,$D11)) -> 22 | W11: =AVERAGE(INDEX(Forecast_Walkforward!$C:$C,$D11-7):INDEX(Forecast_Walkforward!$C:$C,$D11)) -> 23.875 | X11: =SES_Alpha*INDEX(Forecast_Walkforward!$C:$C,$D11)+(1-SES_Alpha)*INDEX(Forecast_Walkforward!$G:$G,$D11) -> 22.616277 | Y11: =MIN(I11:L11) -> 0.13861901 | Z11: =I11<=$Y11+WAPE_Tol -> FALSE | AA11: =J11<=$Y11+WAPE_Tol -> FALSE | AB11: =K11<=$Y11+WAPE_Tol -> TRUE | AC11: =L11<=$Y11+WAPE_Tol -> TRUE | AD11: =MATCH(TRUE(),Z11:AC11,0) -> 3 | AE11: =CHOOSE(AD11,"Naive","MA4","MA8","SES") -> MA8 | AF11: =INDEX(U11:X11,AD11) -> 23.875 | AG11: =INDEX(I11:L11,AD11) -> 0.13861901 | AH11: =INDEX(M11:P11,AD11) -> 0.031575295 | AI11: =INDEX(Q11:T11,AD11) -> 4.6755649 | AJ11: =AG11*H11 -> 199.75 | AK11: =SUM(INDEX(Forecast_Walkforward!$C:$C,$F11):INDEX(Forecast_Walkforward!$C:$C,$G11)) -> 1611 | AL11: =SUM(INDEX(Forecast_Walkforward!$L:$L,$F11):INDEX(Forecast_Walkforward!$L:$L,$G11))/$AK11 -> 0.19056487 | AM11: =SUM(INDEX(Forecast_Walkforward!$M:$M,$F11):INDEX(Forecast_Walkforward!$M:$M,$G11))/$AK11 -> 0.14835506 | AN11: =SUM(INDEX(Forecast_Walkforward!$N:$N,$F11):INDEX(Forecast_Walkforward!$N:$N,$G11))/$AK11 -> 0.1396648 | AO11: =SUM(INDEX(Forecast_Walkforward!$O:$O,$F11):INDEX(Forecast_Walkforward!$O:$O,$G11))/$AK11 -> 0.14567808 | AP11: =_xlfn.STDEV.S(INDEX(Forecast_Walkforward!$H:$H,$F11):INDEX(Forecast_Walkforward!$H:$H,$G11)) -> 7.3146014 | AQ11: =_xlfn.STDEV.S(INDEX(Forecast_Walkforward!$I:$I,$F11):INDEX(Forecast_Walkforward!$I:$I,$G11)) -> 5.3806991 | AR11: =_xlfn.STDEV.S(INDEX(Forecast_Walkforward!$J:$J,$F11):INDEX(Forecast_Walkforward!$J:$J,$G11)) -> 5.120793 | AS11: =_xlfn.STDEV.S(INDEX(Forecast_Walkforward!$K:$K,$F11):INDEX(Forecast_Walkforward!$K:$K,$G11)) -> 5.3437487 | AT11: =MIN(AL11:AO11) -> 0.1396648 | AU11: =AL11<=$AT11+WAPE_Tol -> FALSE | AV11: =AM11<=$AT11+WAPE_Tol -> TRUE | AW11: =AN11<=$AT11+WAPE_Tol -> TRUE | AX11: =AO11<=$AT11+WAPE_Tol -> TRUE | AY11: =MATCH(TRUE(),AU11:AX11,0) -> 2 | AZ11: =CHOOSE(AY11,"Naive","MA4","MA8","SES") -> MA4 | BA11: =INDEX(AP11:AS11,AY11) -> 5.3806991
A12: =Inputs!B45 -> KIT-006 | B12: =Inputs!C45 -> Silicone Utensil Set | C12: =MATCH(A12,Demand_History!$C:$C,0) -> 522 | D12: =C12+Weeks_History-1 -> 625 | E12: =C12+Eval_Start_Week-1 -> 574 | F12: =C12+Cal_Start_Week-1 -> 558 | G12: =C12+Cal_End_Week-1 -> 609 | H12: =SUM(INDEX(Forecast_Walkforward!$C:$C,$E12):INDEX(Forecast_Walkforward!$C:$C,$D12)) -> 2910 | I12: =SUM(INDEX(Forecast_Walkforward!$L:$L,$E12):INDEX(Forecast_Walkforward!$L:$L,$D12))/$H12 -> 0.32268041 | J12: =SUM(INDEX(Forecast_Walkforward!$M:$M,$E12):INDEX(Forecast_Walkforward!$M:$M,$D12))/$H12 -> 0.30249141 | K12: =SUM(INDEX(Forecast_Walkforward!$N:$N,$E12):INDEX(Forecast_Walkforward!$N:$N,$D12))/$H12 -> 0.27079038 | L12: =SUM(INDEX(Forecast_Walkforward!$O:$O,$E12):INDEX(Forecast_Walkforward!$O:$O,$D12))/$H12 -> 0.28376677 | M12: =SUM(INDEX(Forecast_Walkforward!$H:$H,$E12):INDEX(Forecast_Walkforward!$H:$H,$D12))/$H12 -> -0.023024055 | N12: =SUM(INDEX(Forecast_Walkforward!$I:$I,$E12):INDEX(Forecast_Walkforward!$I:$I,$D12))/$H12 -> -0.033247423 | O12: =SUM(INDEX(Forecast_Walkforward!$J:$J,$E12):INDEX(Forecast_Walkforward!$J:$J,$D12))/$H12 -> -0.041237113 | P12: =SUM(INDEX(Forecast_Walkforward!$K:$K,$E12):INDEX(Forecast_Walkforward!$K:$K,$D12))/$H12 -> -0.034934952 | Q12: =_xlfn.STDEV.S(INDEX(Forecast_Walkforward!$H:$H,$E12):INDEX(Forecast_Walkforward!$H:$H,$D12)) -> 22.762488 | R12: =_xlfn.STDEV.S(INDEX(Forecast_Walkforward!$I:$I,$E12):INDEX(Forecast_Walkforward!$I:$I,$D12)) -> 20.779858 | S12: =_xlfn.STDEV.S(INDEX(Forecast_Walkforward!$J:$J,$E12):INDEX(Forecast_Walkforward!$J:$J,$D12)) -> 19.838 | T12: =_xlfn.STDEV.S(INDEX(Forecast_Walkforward!$K:$K,$E12):INDEX(Forecast_Walkforward!$K:$K,$D12)) -> 19.768279 | U12: =INDEX(Forecast_Walkforward!$C:$C,$D12) -> 93 | V12: =AVERAGE(INDEX(Forecast_Walkforward!$C:$C,$D12-3):INDEX(Forecast_Walkforward!$C:$C,$D12)) -> 66 | W12: =AVERAGE(INDEX(Forecast_Walkforward!$C:$C,$D12-7):INDEX(Forecast_Walkforward!$C:$C,$D12)) -> 66.625 | X12: =SES_Alpha*INDEX(Forecast_Walkforward!$C:$C,$D12)+(1-SES_Alpha)*INDEX(Forecast_Walkforward!$G:$G,$D12) -> 71.530846 | Y12: =MIN(I12:L12) -> 0.27079038 | Z12: =I12<=$Y12+WAPE_Tol -> FALSE | AA12: =J12<=$Y12+WAPE_Tol -> FALSE | AB12: =K12<=$Y12+WAPE_Tol -> TRUE | AC12: =L12<=$Y12+WAPE_Tol -> FALSE | AD12: =MATCH(TRUE(),Z12:AC12,0) -> 3 | AE12: =CHOOSE(AD12,"Naive","MA4","MA8","SES") -> MA8 | AF12: =INDEX(U12:X12,AD12) -> 66.625 | AG12: =INDEX(I12:L12,AD12) -> 0.27079038 | AH12: =INDEX(M12:P12,AD12) -> -0.041237113 | AI12: =INDEX(Q12:T12,AD12) -> 19.838 | AJ12: =AG12*H12 -> 788 | AK12: =SUM(INDEX(Forecast_Walkforward!$C:$C,$F12):INDEX(Forecast_Walkforward!$C:$C,$G12)) -> 2761 | AL12: =SUM(INDEX(Forecast_Walkforward!$L:$L,$F12):INDEX(Forecast_Walkforward!$L:$L,$G12))/$AK12 -> 0.37232887 | AM12: =SUM(INDEX(Forecast_Walkforward!$M:$M,$F12):INDEX(Forecast_Walkforward!$M:$M,$G12))/$AK12 -> 0.32461065 | AN12: =SUM(INDEX(Forecast_Walkforward!$N:$N,$F12):INDEX(Forecast_Walkforward!$N:$N,$G12))/$AK12 -> 0.28984064 | AO12: =SUM(INDEX(Forecast_Walkforward!$O:$O,$F12):INDEX(Forecast_Walkforward!$O:$O,$G12))/$AK12 -> 0.30485769 | AP12: =_xlfn.STDEV.S(INDEX(Forecast_Walkforward!$H:$H,$F12):INDEX(Forecast_Walkforward!$H:$H,$G12)) -> 24.401864 | AQ12: =_xlfn.STDEV.S(INDEX(Forecast_Walkforward!$I:$I,$F12):INDEX(Forecast_Walkforward!$I:$I,$G12)) -> 20.920301 | AR12: =_xlfn.STDEV.S(INDEX(Forecast_Walkforward!$J:$J,$F12):INDEX(Forecast_Walkforward!$J:$J,$G12)) -> 20.329749 | AS12: =_xlfn.STDEV.S(INDEX(Forecast_Walkforward!$K:$K,$F12):INDEX(Forecast_Walkforward!$K:$K,$G12)) -> 20.211907 | AT12: =MIN(AL12:AO12) -> 0.28984064 | AU12: =AL12<=$AT12+WAPE_Tol -> FALSE | AV12: =AM12<=$AT12+WAPE_Tol -> FALSE | AW12: =AN12<=$AT12+WAPE_Tol -> TRUE | AX12: =AO12<=$AT12+WAPE_Tol -> FALSE | AY12: =MATCH(TRUE(),AU12:AX12,0) -> 3 | AZ12: =CHOOSE(AY12,"Naive","MA4","MA8","SES") -> MA8 | BA12: =INDEX(AP12:AS12,AY12) -> 20.329749
A13: =Inputs!B46 -> KIT-007 | B13: =Inputs!C46 -> Cast Iron Casserole 5L | C13: =MATCH(A13,Demand_History!$C:$C,0) -> 626 | D13: =C13+Weeks_History-1 -> 729 | E13: =C13+Eval_Start_Week-1 -> 678 | F13: =C13+Cal_Start_Week-1 -> 662 | G13: =C13+Cal_End_Week-1 -> 713 | H13: =SUM(INDEX(Forecast_Walkforward!$C:$C,$E13):INDEX(Forecast_Walkforward!$C:$C,$D13)) -> 386 | I13: =SUM(INDEX(Forecast_Walkforward!$L:$L,$E13):INDEX(Forecast_Walkforward!$L:$L,$D13))/$H13 -> 0.41709845 | J13: =SUM(INDEX(Forecast_Walkforward!$M:$M,$E13):INDEX(Forecast_Walkforward!$M:$M,$D13))/$H13 -> 0.31282383 | K13: =SUM(INDEX(Forecast_Walkforward!$N:$N,$E13):INDEX(Forecast_Walkforward!$N:$N,$D13))/$H13 -> 0.29371762 | L13: =SUM(INDEX(Forecast_Walkforward!$O:$O,$E13):INDEX(Forecast_Walkforward!$O:$O,$D13))/$H13 -> 0.30741071 | M13: =SUM(INDEX(Forecast_Walkforward!$H:$H,$E13):INDEX(Forecast_Walkforward!$H:$H,$D13))/$H13 -> -0.012953368 | N13: =SUM(INDEX(Forecast_Walkforward!$I:$I,$E13):INDEX(Forecast_Walkforward!$I:$I,$D13))/$H13 -> -0.018782383 | O13: =SUM(INDEX(Forecast_Walkforward!$J:$J,$E13):INDEX(Forecast_Walkforward!$J:$J,$D13))/$H13 -> -0.028173575 | P13: =SUM(INDEX(Forecast_Walkforward!$K:$K,$E13):INDEX(Forecast_Walkforward!$K:$K,$D13))/$H13 -> -0.023308287 | Q13: =_xlfn.STDEV.S(INDEX(Forecast_Walkforward!$H:$H,$E13):INDEX(Forecast_Walkforward!$H:$H,$D13)) -> 3.9717612 | R13: =_xlfn.STDEV.S(INDEX(Forecast_Walkforward!$I:$I,$E13):INDEX(Forecast_Walkforward!$I:$I,$D13)) -> 2.9825528 | S13: =_xlfn.STDEV.S(INDEX(Forecast_Walkforward!$J:$J,$E13):INDEX(Forecast_Walkforward!$J:$J,$D13)) -> 2.8252539 | T13: =_xlfn.STDEV.S(INDEX(Forecast_Walkforward!$K:$K,$E13):INDEX(Forecast_Walkforward!$K:$K,$D13)) -> 2.9396325 | U13: =INDEX(Forecast_Walkforward!$C:$C,$D13) -> 9 | V13: =AVERAGE(INDEX(Forecast_Walkforward!$C:$C,$D13-3):INDEX(Forecast_Walkforward!$C:$C,$D13)) -> 8.5 | W13: =AVERAGE(INDEX(Forecast_Walkforward!$C:$C,$D13-7):INDEX(Forecast_Walkforward!$C:$C,$D13)) -> 8.875 | X13: =SES_Alpha*INDEX(Forecast_Walkforward!$C:$C,$D13)+(1-SES_Alpha)*INDEX(Forecast_Walkforward!$G:$G,$D13) -> 8.7888096 | Y13: =MIN(I13:L13) -> 0.29371762 | Z13: =I13<=$Y13+WAPE_Tol -> FALSE | AA13: =J13<=$Y13+WAPE_Tol -> FALSE | AB13: =K13<=$Y13+WAPE_Tol -> TRUE | AC13: =L13<=$Y13+WAPE_Tol -> FALSE | AD13: =MATCH(TRUE(),Z13:AC13,0) -> 3 | AE13: =CHOOSE(AD13,"Naive","MA4","MA8","SES") -> MA8 | AF13: =INDEX(U13:X13,AD13) -> 8.875 | AG13: =INDEX(I13:L13,AD13) -> 0.29371762 | AH13: =INDEX(M13:P13,AD13) -> -0.028173575 | AI13: =INDEX(Q13:T13,AD13) -> 2.8252539 | AJ13: =AG13*H13 -> 113.375 | AK13: =SUM(INDEX(Forecast_Walkforward!$C:$C,$F13):INDEX(Forecast_Walkforward!$C:$C,$G13)) -> 360 | AL13: =SUM(INDEX(Forecast_Walkforward!$L:$L,$F13):INDEX(Forecast_Walkforward!$L:$L,$G13))/$AK13 -> 0.48055556 | AM13: =SUM(INDEX(Forecast_Walkforward!$M:$M,$F13):INDEX(Forecast_Walkforward!$M:$M,$G13))/$AK13 -> 0.36944444 | AN13: =SUM(INDEX(Forecast_Walkforward!$N:$N,$F13):INDEX(Forecast_Walkforward!$N:$N,$G13))/$AK13 -> 0.34756944 | AO13: =SUM(INDEX(Forecast_Walkforward!$O:$O,$F13):INDEX(Forecast_Walkforward!$O:$O,$G13))/$AK13 -> 0.36592269 | AP13: =_xlfn.STDEV.S(INDEX(Forecast_Walkforward!$H:$H,$F13):INDEX(Forecast_Walkforward!$H:$H,$G13)) -> 4.14677 | AQ13: =_xlfn.STDEV.S(INDEX(Forecast_Walkforward!$I:$I,$F13):INDEX(Forecast_Walkforward!$I:$I,$G13)) -> 3.1090809 | AR13: =_xlfn.STDEV.S(INDEX(Forecast_Walkforward!$J:$J,$F13):INDEX(Forecast_Walkforward!$J:$J,$G13)) -> 2.9568715 | AS13: =_xlfn.STDEV.S(INDEX(Forecast_Walkforward!$K:$K,$F13):INDEX(Forecast_Walkforward!$K:$K,$G13)) -> 3.093027 | AT13: =MIN(AL13:AO13) -> 0.34756944 | AU13: =AL13<=$AT13+WAPE_Tol -> FALSE | AV13: =AM13<=$AT13+WAPE_Tol -> FALSE | AW13: =AN13<=$AT13+WAPE_Tol -> TRUE | AX13: =AO13<=$AT13+WAPE_Tol -> FALSE | AY13: =MATCH(TRUE(),AU13:AX13,0) -> 3 | AZ13: =CHOOSE(AY13,"Naive","MA4","MA8","SES") -> MA8 | BA13: =INDEX(AP13:AS13,AY13) -> 2.9568715
A14: =Inputs!B47 -> KIT-008 | B14: =Inputs!C47 -> Espresso Cup Set 6pc | C14: =MATCH(A14,Demand_History!$C:$C,0) -> 730 | D14: =C14+Weeks_History-1 -> 833 | E14: =C14+Eval_Start_Week-1 -> 782 | F14: =C14+Cal_Start_Week-1 -> 766 | G14: =C14+Cal_End_Week-1 -> 817 | H14: =SUM(INDEX(Forecast_Walkforward!$C:$C,$E14):INDEX(Forecast_Walkforward!$C:$C,$D14)) -> 2125 | I14: =SUM(INDEX(Forecast_Walkforward!$L:$L,$E14):INDEX(Forecast_Walkforward!$L:$L,$D14))/$H14 -> 0.10164706 | J14: =SUM(INDEX(Forecast_Walkforward!$M:$M,$E14):INDEX(Forecast_Walkforward!$M:$M,$D14))/$H14 -> 0.087411765 | K14: =SUM(INDEX(Forecast_Walkforward!$N:$N,$E14):INDEX(Forecast_Walkforward!$N:$N,$D14))/$H14 -> 0.087235294 | L14: =SUM(INDEX(Forecast_Walkforward!$O:$O,$E14):INDEX(Forecast_Walkforward!$O:$O,$D14))/$H14 -> 0.082091486 | M14: =SUM(INDEX(Forecast_Walkforward!$H:$H,$E14):INDEX(Forecast_Walkforward!$H:$H,$D14))/$H14 -> 0 | N14: =SUM(INDEX(Forecast_Walkforward!$I:$I,$E14):INDEX(Forecast_Walkforward!$I:$I,$D14))/$H14 -> -0.00011764706 | O14: =SUM(INDEX(Forecast_Walkforward!$J:$J,$E14):INDEX(Forecast_Walkforward!$J:$J,$D14))/$H14 -> -0.0045294118 | P14: =SUM(INDEX(Forecast_Walkforward!$K:$K,$E14):INDEX(Forecast_Walkforward!$K:$K,$D14))/$H14 -> -0.0016359657 | Q14: =_xlfn.STDEV.S(INDEX(Forecast_Walkforward!$H:$H,$E14):INDEX(Forecast_Walkforward!$H:$H,$D14)) -> 5.5093503 | R14: =_xlfn.STDEV.S(INDEX(Forecast_Walkforward!$I:$I,$E14):INDEX(Forecast_Walkforward!$I:$I,$D14)) -> 4.6122945 | S14: =_xlfn.STDEV.S(INDEX(Forecast_Walkforward!$J:$J,$E14):INDEX(Forecast_Walkforward!$J:$J,$D14)) -> 4.5042525 | T14: =_xlfn.STDEV.S(INDEX(Forecast_Walkforward!$K:$K,$E14):INDEX(Forecast_Walkforward!$K:$K,$D14)) -> 4.4191618 | U14: =INDEX(Forecast_Walkforward!$C:$C,$D14) -> 40 | V14: =AVERAGE(INDEX(Forecast_Walkforward!$C:$C,$D14-3):INDEX(Forecast_Walkforward!$C:$C,$D14)) -> 41.5 | W14: =AVERAGE(INDEX(Forecast_Walkforward!$C:$C,$D14-7):INDEX(Forecast_Walkforward!$C:$C,$D14)) -> 41.5 | X14: =SES_Alpha*INDEX(Forecast_Walkforward!$C:$C,$D14)+(1-SES_Alpha)*INDEX(Forecast_Walkforward!$G:$G,$D14) -> 40.899519 | Y14: =MIN(I14:L14) -> 0.082091486 | Z14: =I14<=$Y14+WAPE_Tol -> FALSE | AA14: =J14<=$Y14+WAPE_Tol -> TRUE | AB14: =K14<=$Y14+WAPE_Tol -> TRUE | AC14: =L14<=$Y14+WAPE_Tol -> TRUE | AD14: =MATCH(TRUE(),Z14:AC14,0) -> 2 | AE14: =CHOOSE(AD14,"Naive","MA4","MA8","SES") -> MA4 | AF14: =INDEX(U14:X14,AD14) -> 41.5 | AG14: =INDEX(I14:L14,AD14) -> 0.087411765 | AH14: =INDEX(M14:P14,AD14) -> -0.00011764706 | AI14: =INDEX(Q14:T14,AD14) -> 4.6122945 | AJ14: =AG14*H14 -> 185.75 | AK14: =SUM(INDEX(Forecast_Walkforward!$C:$C,$F14):INDEX(Forecast_Walkforward!$C:$C,$G14)) -> 2115 | AL14: =SUM(INDEX(Forecast_Walkforward!$L:$L,$F14):INDEX(Forecast_Walkforward!$L:$L,$G14))/$AK14 -> 0.11583924 | AM14: =SUM(INDEX(Forecast_Walkforward!$M:$M,$F14):INDEX(Forecast_Walkforward!$M:$M,$G14))/$AK14 -> 0.095508274 | AN14: =SUM(INDEX(Forecast_Walkforward!$N:$N,$F14):INDEX(Forecast_Walkforward!$N:$N,$G14))/$AK14 -> 0.088947991 | AO14: =SUM(INDEX(Forecast_Walkforward!$O:$O,$F14):INDEX(Forecast_Walkforward!$O:$O,$G14))/$AK14 -> 0.088667661 | AP14: =_xlfn.STDEV.S(INDEX(Forecast_Walkforward!$H:$H,$F14):INDEX(Forecast_Walkforward!$H:$H,$G14)) -> 5.9718735 | AQ14: =_xlfn.STDEV.S(INDEX(Forecast_Walkforward!$I:$I,$F14):INDEX(Forecast_Walkforward!$I:$I,$G14)) -> 4.9357486 | AR14: =_xlfn.STDEV.S(INDEX(Forecast_Walkforward!$J:$J,$F14):INDEX(Forecast_Walkforward!$J:$J,$G14)) -> 4.6532497 | AS14: =_xlfn.STDEV.S(INDEX(Forecast_Walkforward!$K:$K,$F14):INDEX(Forecast_Walkforward!$K:$K,$G14)) -> 4.6695842 | AT14: =MIN(AL14:AO14) -> 0.088667661 | AU14: =AL14<=$AT14+WAPE_Tol -> FALSE | AV14: =AM14<=$AT14+WAPE_Tol -> TRUE | AW14: =AN14<=$AT14+WAPE_Tol -> TRUE | AX14: =AO14<=$AT14+WAPE_Tol -> TRUE | AY14: =MATCH(TRUE(),AU14:AX14,0) -> 2 | AZ14: =CHOOSE(AY14,"Naive","MA4","MA8","SES") -> MA4 | BA14: =INDEX(AP14:AS14,AY14) -> 4.9357486
A15: =Inputs!B48 -> KIT-009 | B15: =Inputs!C48 -> Digital Kitchen Scale | C15: =MATCH(A15,Demand_History!$C:$C,0) -> 834 | D15: =C15+Weeks_History-1 -> 937 | E15: =C15+Eval_Start_Week-1 -> 886 | F15: =C15+Cal_Start_Week-1 -> 870 | G15: =C15+Cal_End_Week-1 -> 921 | H15: =SUM(INDEX(Forecast_Walkforward!$C:$C,$E15):INDEX(Forecast_Walkforward!$C:$C,$D15)) -> 1845 | I15: =SUM(INDEX(Forecast_Walkforward!$L:$L,$E15):INDEX(Forecast_Walkforward!$L:$L,$D15))/$H15 -> 0.14905149 | J15: =SUM(INDEX(Forecast_Walkforward!$M:$M,$E15):INDEX(Forecast_Walkforward!$M:$M,$D15))/$H15 -> 0.10921409 | K15: =SUM(INDEX(Forecast_Walkforward!$N:$N,$E15):INDEX(Forecast_Walkforward!$N:$N,$D15))/$H15 -> 0.11124661 | L15: =SUM(INDEX(Forecast_Walkforward!$O:$O,$E15):INDEX(Forecast_Walkforward!$O:$O,$D15))/$H15 -> 0.10824638 | M15: =SUM(INDEX(Forecast_Walkforward!$H:$H,$E15):INDEX(Forecast_Walkforward!$H:$H,$D15))/$H15 -> -0.0070460705 | N15: =SUM(INDEX(Forecast_Walkforward!$I:$I,$E15):INDEX(Forecast_Walkforward!$I:$I,$D15))/$H15 -> -0.01598916 | O15: =SUM(INDEX(Forecast_Walkforward!$J:$J,$E15):INDEX(Forecast_Walkforward!$J:$J,$D15))/$H15 -> -0.030216802 | P15: =SUM(INDEX(Forecast_Walkforward!$K:$K,$E15):INDEX(Forecast_Walkforward!$K:$K,$D15))/$H15 -> -0.021742456 | Q15: =_xlfn.STDEV.S(INDEX(Forecast_Walkforward!$H:$H,$E15):INDEX(Forecast_Walkforward!$H:$H,$D15)) -> 6.4378629 | R15: =_xlfn.STDEV.S(INDEX(Forecast_Walkforward!$I:$I,$E15):INDEX(Forecast_Walkforward!$I:$I,$D15)) -> 4.8535199 | S15: =_xlfn.STDEV.S(INDEX(Forecast_Walkforward!$J:$J,$E15):INDEX(Forecast_Walkforward!$J:$J,$D15)) -> 5.1089446 | T15: =_xlfn.STDEV.S(INDEX(Forecast_Walkforward!$K:$K,$E15):INDEX(Forecast_Walkforward!$K:$K,$D15)) -> 4.9473142 | U15: =INDEX(Forecast_Walkforward!$C:$C,$D15) -> 36 | V15: =AVERAGE(INDEX(Forecast_Walkforward!$C:$C,$D15-3):INDEX(Forecast_Walkforward!$C:$C,$D15)) -> 39.5 | W15: =AVERAGE(INDEX(Forecast_Walkforward!$C:$C,$D15-7):INDEX(Forecast_Walkforward!$C:$C,$D15)) -> 41.25 | X15: =SES_Alpha*INDEX(Forecast_Walkforward!$C:$C,$D15)+(1-SES_Alpha)*INDEX(Forecast_Walkforward!$G:$G,$D15) -> 39.715593 | Y15: =MIN(I15:L15) -> 0.10824638 | Z15: =I15<=$Y15+WAPE_Tol -> FALSE | AA15: =J15<=$Y15+WAPE_Tol -> TRUE | AB15: =K15<=$Y15+WAPE_Tol -> TRUE | AC15: =L15<=$Y15+WAPE_Tol -> TRUE | AD15: =MATCH(TRUE(),Z15:AC15,0) -> 2 | AE15: =CHOOSE(AD15,"Naive","MA4","MA8","SES") -> MA4 | AF15: =INDEX(U15:X15,AD15) -> 39.5 | AG15: =INDEX(I15:L15,AD15) -> 0.10921409 | AH15: =INDEX(M15:P15,AD15) -> -0.01598916 | AI15: =INDEX(Q15:T15,AD15) -> 4.8535199 | AJ15: =AG15*H15 -> 201.5 | AK15: =SUM(INDEX(Forecast_Walkforward!$C:$C,$F15):INDEX(Forecast_Walkforward!$C:$C,$G15)) -> 1693 | AL15: =SUM(INDEX(Forecast_Walkforward!$L:$L,$F15):INDEX(Forecast_Walkforward!$L:$L,$G15))/$AK15 -> 0.15416421 | AM15: =SUM(INDEX(Forecast_Walkforward!$M:$M,$F15):INDEX(Forecast_Walkforward!$M:$M,$G15))/$AK15 -> 0.11311282 | AN15: =SUM(INDEX(Forecast_Walkforward!$N:$N,$F15):INDEX(Forecast_Walkforward!$N:$N,$G15))/$AK15 -> 0.11488482 | AO15: =SUM(INDEX(Forecast_Walkforward!$O:$O,$F15):INDEX(Forecast_Walkforward!$O:$O,$G15))/$AK15 -> 0.11643772 | AP15: =_xlfn.STDEV.S(INDEX(Forecast_Walkforward!$H:$H,$F15):INDEX(Forecast_Walkforward!$H:$H,$G15)) -> 6.2856525 | AQ15: =_xlfn.STDEV.S(INDEX(Forecast_Walkforward!$I:$I,$F15):INDEX(Forecast_Walkforward!$I:$I,$G15)) -> 4.6944236 | AR15: =_xlfn.STDEV.S(INDEX(Forecast_Walkforward!$J:$J,$F15):INDEX(Forecast_Walkforward!$J:$J,$G15)) -> 4.8612561 | AS15: =_xlfn.STDEV.S(INDEX(Forecast_Walkforward!$K:$K,$F15):INDEX(Forecast_Walkforward!$K:$K,$G15)) -> 4.850543 | AT15: =MIN(AL15:AO15) -> 0.11311282 | AU15: =AL15<=$AT15+WAPE_Tol -> FALSE | AV15: =AM15<=$AT15+WAPE_Tol -> TRUE | AW15: =AN15<=$AT15+WAPE_Tol -> TRUE | AX15: =AO15<=$AT15+WAPE_Tol -> TRUE | AY15: =MATCH(TRUE(),AU15:AX15,0) -> 2 | AZ15: =CHOOSE(AY15,"Naive","MA4","MA8","SES") -> MA4 | BA15: =INDEX(AP15:AS15,AY15) -> 4.6944236
A16: =Inputs!B49 -> KIT-010 | B16: =Inputs!C49 -> Measuring Jug 1L | C16: =MATCH(A16,Demand_History!$C:$C,0) -> 938 | D16: =C16+Weeks_History-1 -> 1041 | E16: =C16+Eval_Start_Week-1 -> 990 | F16: =C16+Cal_Start_Week-1 -> 974 | G16: =C16+Cal_End_Week-1 -> 1025 | H16: =SUM(INDEX(Forecast_Walkforward!$C:$C,$E16):INDEX(Forecast_Walkforward!$C:$C,$D16)) -> 5105 | I16: =SUM(INDEX(Forecast_Walkforward!$L:$L,$E16):INDEX(Forecast_Walkforward!$L:$L,$D16))/$H16 -> 0.12693438 | J16: =SUM(INDEX(Forecast_Walkforward!$M:$M,$E16):INDEX(Forecast_Walkforward!$M:$M,$D16))/$H16 -> 0.08956905 | K16: =SUM(INDEX(Forecast_Walkforward!$N:$N,$E16):INDEX(Forecast_Walkforward!$N:$N,$D16))/$H16 -> 0.087047013 | L16: =SUM(INDEX(Forecast_Walkforward!$O:$O,$E16):INDEX(Forecast_Walkforward!$O:$O,$D16))/$H16 -> 0.090343713 | M16: =SUM(INDEX(Forecast_Walkforward!$H:$H,$E16):INDEX(Forecast_Walkforward!$H:$H,$D16))/$H16 -> 0.00078354554 | N16: =SUM(INDEX(Forecast_Walkforward!$I:$I,$E16):INDEX(Forecast_Walkforward!$I:$I,$D16))/$H16 -> -0.0020078355 | O16: =SUM(INDEX(Forecast_Walkforward!$J:$J,$E16):INDEX(Forecast_Walkforward!$J:$J,$D16))/$H16 -> -0.004970617 | P16: =SUM(INDEX(Forecast_Walkforward!$K:$K,$E16):INDEX(Forecast_Walkforward!$K:$K,$D16))/$H16 -> -0.0023274887 | Q16: =_xlfn.STDEV.S(INDEX(Forecast_Walkforward!$H:$H,$E16):INDEX(Forecast_Walkforward!$H:$H,$D16)) -> 15.299425 | R16: =_xlfn.STDEV.S(INDEX(Forecast_Walkforward!$I:$I,$E16):INDEX(Forecast_Walkforward!$I:$I,$D16)) -> 10.37535 | S16: =_xlfn.STDEV.S(INDEX(Forecast_Walkforward!$J:$J,$E16):INDEX(Forecast_Walkforward!$J:$J,$D16)) -> 10.22415 | T16: =_xlfn.STDEV.S(INDEX(Forecast_Walkforward!$K:$K,$E16):INDEX(Forecast_Walkforward!$K:$K,$D16)) -> 10.616225 | U16: =INDEX(Forecast_Walkforward!$C:$C,$D16) -> 91 | V16: =AVERAGE(INDEX(Forecast_Walkforward!$C:$C,$D16-3):INDEX(Forecast_Walkforward!$C:$C,$D16)) -> 101 | W16: =AVERAGE(INDEX(Forecast_Walkforward!$C:$C,$D16-7):INDEX(Forecast_Walkforward!$C:$C,$D16)) -> 99.25 | X16: =SES_Alpha*INDEX(Forecast_Walkforward!$C:$C,$D16)+(1-SES_Alpha)*INDEX(Forecast_Walkforward!$G:$G,$D16) -> 97.933094 | Y16: =MIN(I16:L16) -> 0.087047013 | Z16: =I16<=$Y16+WAPE_Tol -> FALSE | AA16: =J16<=$Y16+WAPE_Tol -> TRUE | AB16: =K16<=$Y16+WAPE_Tol -> TRUE | AC16: =L16<=$Y16+WAPE_Tol -> TRUE | AD16: =MATCH(TRUE(),Z16:AC16,0) -> 2 | AE16: =CHOOSE(AD16,"Naive","MA4","MA8","SES") -> MA4 | AF16: =INDEX(U16:X16,AD16) -> 101 | AG16: =INDEX(I16:L16,AD16) -> 0.08956905 | AH16: =INDEX(M16:P16,AD16) -> -0.0020078355 | AI16: =INDEX(Q16:T16,AD16) -> 10.37535 | AJ16: =AG16*H16 -> 457.25 | AK16: =SUM(INDEX(Forecast_Walkforward!$C:$C,$F16):INDEX(Forecast_Walkforward!$C:$C,$G16)) -> 5102 | AL16: =SUM(INDEX(Forecast_Walkforward!$L:$L,$F16):INDEX(Forecast_Walkforward!$L:$L,$G16))/$AK16 -> 0.10623285 | AM16: =SUM(INDEX(Forecast_Walkforward!$M:$M,$F16):INDEX(Forecast_Walkforward!$M:$M,$G16))/$AK16 -> 0.08869071 | AN16: =SUM(INDEX(Forecast_Walkforward!$N:$N,$F16):INDEX(Forecast_Walkforward!$N:$N,$G16))/$AK16 -> 0.081953156 | AO16: =SUM(INDEX(Forecast_Walkforward!$O:$O,$F16):INDEX(Forecast_Walkforward!$O:$O,$G16))/$AK16 -> 0.084069645 | AP16: =_xlfn.STDEV.S(INDEX(Forecast_Walkforward!$H:$H,$F16):INDEX(Forecast_Walkforward!$H:$H,$G16)) -> 13.285188 | AQ16: =_xlfn.STDEV.S(INDEX(Forecast_Walkforward!$I:$I,$F16):INDEX(Forecast_Walkforward!$I:$I,$G16)) -> 10.066952 | AR16: =_xlfn.STDEV.S(INDEX(Forecast_Walkforward!$J:$J,$F16):INDEX(Forecast_Walkforward!$J:$J,$G16)) -> 9.7424638 | AS16: =_xlfn.STDEV.S(INDEX(Forecast_Walkforward!$K:$K,$F16):INDEX(Forecast_Walkforward!$K:$K,$G16)) -> 9.7633968 | AT16: =MIN(AL16:AO16) -> 0.081953156 | AU16: =AL16<=$AT16+WAPE_Tol -> FALSE | AV16: =AM16<=$AT16+WAPE_Tol -> TRUE | AW16: =AN16<=$AT16+WAPE_Tol -> TRUE | AX16: =AO16<=$AT16+WAPE_Tol -> TRUE | AY16: =MATCH(TRUE(),AU16:AX16,0) -> 2 | AZ16: =CHOOSE(AY16,"Naive","MA4","MA8","SES") -> MA4 | BA16: =INDEX(AP16:AS16,AY16) -> 10.066952
A17: =Inputs!B50 -> BTH-001 | B17: =Inputs!C50 -> Bath Towel 70x140 Grey | C17: =MATCH(A17,Demand_History!$C:$C,0) -> 1042 | D17: =C17+Weeks_History-1 -> 1145 | E17: =C17+Eval_Start_Week-1 -> 1094 | F17: =C17+Cal_Start_Week-1 -> 1078 | G17: =C17+Cal_End_Week-1 -> 1129 | H17: =SUM(INDEX(Forecast_Walkforward!$C:$C,$E17):INDEX(Forecast_Walkforward!$C:$C,$D17)) -> 6085 | I17: =SUM(INDEX(Forecast_Walkforward!$L:$L,$E17):INDEX(Forecast_Walkforward!$L:$L,$D17))/$H17 -> 0.18997535 | J17: =SUM(INDEX(Forecast_Walkforward!$M:$M,$E17):INDEX(Forecast_Walkforward!$M:$M,$D17))/$H17 -> 0.13323747 | K17: =SUM(INDEX(Forecast_Walkforward!$N:$N,$E17):INDEX(Forecast_Walkforward!$N:$N,$D17))/$H17 -> 0.12481512 | L17: =SUM(INDEX(Forecast_Walkforward!$O:$O,$E17):INDEX(Forecast_Walkforward!$O:$O,$D17))/$H17 -> 0.13400852 | M17: =SUM(INDEX(Forecast_Walkforward!$H:$H,$E17):INDEX(Forecast_Walkforward!$H:$H,$D17))/$H17 -> 0.0019720624 | N17: =SUM(INDEX(Forecast_Walkforward!$I:$I,$E17):INDEX(Forecast_Walkforward!$I:$I,$D17))/$H17 -> 0.0022596549 | O17: =SUM(INDEX(Forecast_Walkforward!$J:$J,$E17):INDEX(Forecast_Walkforward!$J:$J,$D17))/$H17 -> 0.0022596549 | P17: =SUM(INDEX(Forecast_Walkforward!$K:$K,$E17):INDEX(Forecast_Walkforward!$K:$K,$D17))/$H17 -> 0.0024115462 | Q17: =_xlfn.STDEV.S(INDEX(Forecast_Walkforward!$H:$H,$E17):INDEX(Forecast_Walkforward!$H:$H,$D17)) -> 27.118921 | R17: =_xlfn.STDEV.S(INDEX(Forecast_Walkforward!$I:$I,$E17):INDEX(Forecast_Walkforward!$I:$I,$D17)) -> 18.698158 | S17: =_xlfn.STDEV.S(INDEX(Forecast_Walkforward!$J:$J,$E17):INDEX(Forecast_Walkforward!$J:$J,$D17)) -> 17.848948 | T17: =_xlfn.STDEV.S(INDEX(Forecast_Walkforward!$K:$K,$E17):INDEX(Forecast_Walkforward!$K:$K,$D17)) -> 18.752751 | U17: =INDEX(Forecast_Walkforward!$C:$C,$D17) -> 103 | V17: =AVERAGE(INDEX(Forecast_Walkforward!$C:$C,$D17-3):INDEX(Forecast_Walkforward!$C:$C,$D17)) -> 106 | W17: =AVERAGE(INDEX(Forecast_Walkforward!$C:$C,$D17-7):INDEX(Forecast_Walkforward!$C:$C,$D17)) -> 109.75 | X17: =SES_Alpha*INDEX(Forecast_Walkforward!$C:$C,$D17)+(1-SES_Alpha)*INDEX(Forecast_Walkforward!$G:$G,$D17) -> 109.23514 | Y17: =MIN(I17:L17) -> 0.12481512 | Z17: =I17<=$Y17+WAPE_Tol -> FALSE | AA17: =J17<=$Y17+WAPE_Tol -> TRUE | AB17: =K17<=$Y17+WAPE_Tol -> TRUE | AC17: =L17<=$Y17+WAPE_Tol -> TRUE | AD17: =MATCH(TRUE(),Z17:AC17,0) -> 2 | AE17: =CHOOSE(AD17,"Naive","MA4","MA8","SES") -> MA4 | AF17: =INDEX(U17:X17,AD17) -> 106 | AG17: =INDEX(I17:L17,AD17) -> 0.13323747 | AH17: =INDEX(M17:P17,AD17) -> 0.0022596549 | AI17: =INDEX(Q17:T17,AD17) -> 18.698158 | AJ17: =AG17*H17 -> 810.75 | AK17: =SUM(INDEX(Forecast_Walkforward!$C:$C,$F17):INDEX(Forecast_Walkforward!$C:$C,$G17)) -> 6213 | AL17: =SUM(INDEX(Forecast_Walkforward!$L:$L,$F17):INDEX(Forecast_Walkforward!$L:$L,$G17))/$AK17 -> 0.19668437 | AM17: =SUM(INDEX(Forecast_Walkforward!$M:$M,$F17):INDEX(Forecast_Walkforward!$M:$M,$G17))/$AK17 -> 0.14413327 | AN17: =SUM(INDEX(Forecast_Walkforward!$N:$N,$F17):INDEX(Forecast_Walkforward!$N:$N,$G17))/$AK17 -> 0.13387253 | AO17: =SUM(INDEX(Forecast_Walkforward!$O:$O,$F17):INDEX(Forecast_Walkforward!$O:$O,$G17))/$AK17 -> 0.14303468 | AP17: =_xlfn.STDEV.S(INDEX(Forecast_Walkforward!$H:$H,$F17):INDEX(Forecast_Walkforward!$H:$H,$G17)) -> 28.368694 | AQ17: =_xlfn.STDEV.S(INDEX(Forecast_Walkforward!$I:$I,$F17):INDEX(Forecast_Walkforward!$I:$I,$G17)) -> 20.105125 | AR17: =_xlfn.STDEV.S(INDEX(Forecast_Walkforward!$J:$J,$F17):INDEX(Forecast_Walkforward!$J:$J,$G17)) -> 18.915114 | AS17: =_xlfn.STDEV.S(INDEX(Forecast_Walkforward!$K:$K,$F17):INDEX(Forecast_Walkforward!$K:$K,$G17)) -> 20.004516 | AT17: =MIN(AL17:AO17) -> 0.13387253 | AU17: =AL17<=$AT17+WAPE_Tol -> FALSE | AV17: =AM17<=$AT17+WAPE_Tol -> FALSE | AW17: =AN17<=$AT17+WAPE_Tol -> TRUE | AX17: =AO17<=$AT17+WAPE_Tol -> TRUE | AY17: =MATCH(TRUE(),AU17:AX17,0) -> 3 | AZ17: =CHOOSE(AY17,"Naive","MA4","MA8","SES") -> MA8 | BA17: =INDEX(AP17:AS17,AY17) -> 18.915114
A18: =Inputs!B51 -> BTH-002 | B18: =Inputs!C51 -> Hand Towel 50x100 White | C18: =MATCH(A18,Demand_History!$C:$C,0) -> 1146 | D18: =C18+Weeks_History-1 -> 1249 | E18: =C18+Eval_Start_Week-1 -> 1198 | F18: =C18+Cal_Start_Week-1 -> 1182 | G18: =C18+Cal_End_Week-1 -> 1233 | H18: =SUM(INDEX(Forecast_Walkforward!$C:$C,$E18):INDEX(Forecast_Walkforward!$C:$C,$D18)) -> 7872 | I18: =SUM(INDEX(Forecast_Walkforward!$L:$L,$E18):INDEX(Forecast_Walkforward!$L:$L,$D18))/$H18 -> 0.10086382 | J18: =SUM(INDEX(Forecast_Walkforward!$M:$M,$E18):INDEX(Forecast_Walkforward!$M:$M,$D18))/$H18 -> 0.070915904 | K18: =SUM(INDEX(Forecast_Walkforward!$N:$N,$E18):INDEX(Forecast_Walkforward!$N:$N,$D18))/$H18 -> 0.070296621 | L18: =SUM(INDEX(Forecast_Walkforward!$O:$O,$E18):INDEX(Forecast_Walkforward!$O:$O,$D18))/$H18 -> 0.072404702 | M18: =SUM(INDEX(Forecast_Walkforward!$H:$H,$E18):INDEX(Forecast_Walkforward!$H:$H,$D18))/$H18 -> 0.0017784553 | N18: =SUM(INDEX(Forecast_Walkforward!$I:$I,$E18):INDEX(Forecast_Walkforward!$I:$I,$D18))/$H18 -> 0.00390625 | O18: =SUM(INDEX(Forecast_Walkforward!$J:$J,$E18):INDEX(Forecast_Walkforward!$J:$J,$D18))/$H18 -> 0.0066533283 | P18: =SUM(INDEX(Forecast_Walkforward!$K:$K,$E18):INDEX(Forecast_Walkforward!$K:$K,$D18))/$H18 -> 0.004717227 | Q18: =_xlfn.STDEV.S(INDEX(Forecast_Walkforward!$H:$H,$E18):INDEX(Forecast_Walkforward!$H:$H,$D18)) -> 19.981477 | R18: =_xlfn.STDEV.S(INDEX(Forecast_Walkforward!$I:$I,$E18):INDEX(Forecast_Walkforward!$I:$I,$D18)) -> 14.063496 | S18: =_xlfn.STDEV.S(INDEX(Forecast_Walkforward!$J:$J,$E18):INDEX(Forecast_Walkforward!$J:$J,$D18)) -> 13.872613 | T18: =_xlfn.STDEV.S(INDEX(Forecast_Walkforward!$K:$K,$E18):INDEX(Forecast_Walkforward!$K:$K,$D18)) -> 14.388641 | U18: =INDEX(Forecast_Walkforward!$C:$C,$D18) -> 148 | V18: =AVERAGE(INDEX(Forecast_Walkforward!$C:$C,$D18-3):INDEX(Forecast_Walkforward!$C:$C,$D18)) -> 146.25 | W18: =AVERAGE(INDEX(Forecast_Walkforward!$C:$C,$D18-7):INDEX(Forecast_Walkforward!$C:$C,$D18)) -> 148.125 | X18: =SES_Alpha*INDEX(Forecast_Walkforward!$C:$C,$D18)+(1-SES_Alpha)*INDEX(Forecast_Walkforward!$G:$G,$D18) -> 145.85158 | Y18: =MIN(I18:L18) -> 0.070296621 | Z18: =I18<=$Y18+WAPE_Tol -> FALSE | AA18: =J18<=$Y18+WAPE_Tol -> TRUE | AB18: =K18<=$Y18+WAPE_Tol -> TRUE | AC18: =L18<=$Y18+WAPE_Tol -> TRUE | AD18: =MATCH(TRUE(),Z18:AC18,0) -> 2 | AE18: =CHOOSE(AD18,"Naive","MA4","MA8","SES") -> MA4 | AF18: =INDEX(U18:X18,AD18) -> 146.25 | AG18: =INDEX(I18:L18,AD18) -> 0.070915904 | AH18: =INDEX(M18:P18,AD18) -> 0.00390625 | AI18: =INDEX(Q18:T18,AD18) -> 14.063496 | AJ18: =AG18*H18 -> 558.25 | AK18: =SUM(INDEX(Forecast_Walkforward!$C:$C,$F18):INDEX(Forecast_Walkforward!$C:$C,$G18)) -> 7961 | AL18: =SUM(INDEX(Forecast_Walkforward!$L:$L,$F18):INDEX(Forecast_Walkforward!$L:$L,$G18))/$AK18 -> 0.10689612 | AM18: =SUM(INDEX(Forecast_Walkforward!$M:$M,$F18):INDEX(Forecast_Walkforward!$M:$M,$G18))/$AK18 -> 0.075493029 | AN18: =SUM(INDEX(Forecast_Walkforward!$N:$N,$F18):INDEX(Forecast_Walkforward!$N:$N,$G18))/$AK18 -> 0.077392915 | AO18: =SUM(INDEX(Forecast_Walkforward!$O:$O,$F18):INDEX(Forecast_Walkforward!$O:$O,$G18))/$AK18 -> 0.077646762 | AP18: =_xlfn.STDEV.S(INDEX(Forecast_Walkforward!$H:$H,$F18):INDEX(Forecast_Walkforward!$H:$H,$G18)) -> 20.935034 | AQ18: =_xlfn.STDEV.S(INDEX(Forecast_Walkforward!$I:$I,$F18):INDEX(Forecast_Walkforward!$I:$I,$G18)) -> 14.78887 | AR18: =_xlfn.STDEV.S(INDEX(Forecast_Walkforward!$J:$J,$F18):INDEX(Forecast_Walkforward!$J:$J,$G18)) -> 15.001634 | AS18: =_xlfn.STDEV.S(INDEX(Forecast_Walkforward!$K:$K,$F18):INDEX(Forecast_Walkforward!$K:$K,$G18)) -> 15.211368 | AT18: =MIN(AL18:AO18) -> 0.075493029 | AU18: =AL18<=$AT18+WAPE_Tol -> FALSE | AV18: =AM18<=$AT18+WAPE_Tol -> TRUE | AW18: =AN18<=$AT18+WAPE_Tol -> TRUE | AX18: =AO18<=$AT18+WAPE_Tol -> TRUE | AY18: =MATCH(TRUE(),AU18:AX18,0) -> 2 | AZ18: =CHOOSE(AY18,"Naive","MA4","MA8","SES") -> MA4 | BA18: =INDEX(AP18:AS18,AY18) -> 14.78887
